<?xml version="1.0" encoding="utf-8"?>
<robot xmlns:xacro="http://www.ros.org/wiki/xacro"
       name="leo_description">
  <xacro:arg name="robot_namespace" default="/" />
  <link name="base_link">
    <inertial>
      <mass value="1.584994"/>
      <origin xyz="-0.019662 0.011643 -0.031802"/>
      <inertia ixx="0.01042" ixy="0.001177" ixz="-0.0008871" iyy="0.01045" iyz="0.0002226" izz="0.01817"/>
    </inertial>
    <visual>
      <origin xyz="0 0 0" rpy="0 0 0" />
      <geometry>
        <mesh filename="package://leo_description/models/base.dae"/>
      </geometry>
    </visual>
  </link>



  <link name="base_footprint"/>

  <xacro:property name="M_PI" value="3.14159"/>

  <xacro:macro name="wheel_link" params="name model"> 
    <link name="wheel_${name}_link">
      <!-- TODO: inertia parameters are incoreect for this type of wheel -->
      <inertial>
	<mass value="0.637" />
	<origin xyz="0 0 0" />
	<inertia  ixx="0.02467" ixy="0" ixz="0" iyy="0.04411" iyz="0" izz="0.02467" />
      </inertial>
      <visual>
        <origin xyz="0 0 0" rpy="0 0 0"/>
        <geometry>
          <mesh filename="package://leo_description/models/wheel_${model}.dae"/>
        </geometry>
      </visual>
      <collision>
	<origin xyz="0 0 0" rpy="${M_PI/2} 0 0" />
	<geometry>
		<cylinder length="0.07" radius="0.0625" />
	</geometry>
    </collision>
    </link>
  </xacro:macro>

  <xacro:wheel_link name="FL" model="left"/>
  <xacro:wheel_link name="FR" model="right"/>
  <xacro:wheel_link name="RL" model="left"/>
  <xacro:wheel_link name="RR" model="right"/>
  

  <joint name="wheel_FL_joint" type="continuous">
    <origin xyz="0.1472 0.1114 -0.1353" rpy="0 0 ${M_PI}"/>
    <parent link="base_footprint"/>
    <child link="wheel_FL_link"/>
    <axis xyz="0 -1 0"/>
  </joint>

  <joint name="wheel_FR_joint" type="continuous">
    <origin xyz="0.1472 -0.1114 -0.1353" rpy="0 0 0"/>
    <parent link="base_footprint"/>
    <child link="wheel_FR_link"/>
    <axis xyz="0 1 0"/>
  </joint>

  <joint name="wheel_RL_joint" type="continuous">
    <origin xyz="-0.1419 0.1114 -0.1353" rpy="0 0 ${M_PI}"/>
    <parent link="base_footprint"/>
    <child link="wheel_RL_link"/>
    <axis xyz="0 -1 0"/>
  </joint>

  <joint name="wheel_RR_joint" type="continuous">
    <origin xyz="-0.1419 -0.1114 -0.1353" rpy="0 0 0"/>
    <parent link="base_footprint"/>
    <child link="wheel_RR_link"/>
    <axis xyz="0 1 0"/>
  </joint>

  <link name="camera_frame"/>

  <joint name="camera_joint" type="fixed">
      <origin xyz="0.0971 0 -0.0427" rpy="${-pi/2 - 0.2094} 0 ${-M_PI/2}"/>
      <parent link="base_footprint"/>
      <child link="camera_frame"/>
  </joint>

<joint name="footprint_joint" type="fixed">
      <origin xyz="0 0 -0.19783" rpy="0 0 0"/>
      <parent link="base_link"/>
      <child link="base_footprint"/>
  </joint>
 

  <!-- Added gazebo_ros control -->
  <gazebo>
    <plugin name="gazebo_ros_control" filename="libgazebo_ros_control.so">
      <robotNamespace>$(arg robot_namespace)</robotNamespace>
    </plugin>
  </gazebo>

</robot>
